Workbook

Sheet Absen PG
A1: TK SWASTA METHODIST-11 | S1: S
A2: DAFTAR NAMA MURID T.P. 2025/2026 | T2: I | AJ2: PG
A3: Kelas | C3: =" : " & IF(AJ2="","",AJ2)
A4: Walikelas | C4: =IFERROR(" : " &VLOOKUP($A$7&$AJ$2,#REF!,6,FALSE), "")
A5: Nomor | C5: Nama | D5: April
A6: Urt | B6: Induk | D6: 1 | E6: 2 | F6: 3 | G6: 4 | H6: 5 | I6: 6 | J6: 7 | K6: 8 | L6: 9 | M6: 10 | N6: 11 | O6: 12 | P6: 13 | Q6: 14 | R6: 15 | S6: 16 | T6: 17 | U6: 18 | V6: 19 | W6: 20 | X6: 21 | Y6: 22 | Z6: 23 | AA6: 24 | AB6: 25 | AC6: 26 | AD6: 27 | AE6: 28 | AF6: 29 | AG6: 30 | AH6: 31 | AL6: S | AM6: I | AN6: A | AO6: Total
A7: 1 | B7: =IFERROR(VLOOKUP(A7&$AJ$2,Data!$A$2:$AM$131,3,FALSE), "") | C7: =IFERROR(VLOOKUP(A7&$AJ$2,Data!$A$2:$AM$131,4,FALSE), "") | AK7: S | AL7: =COUNTIF(D7:AH7,"S") | AM7: =COUNTIF(D7:AH7,"I") | AN7: =COUNTIF(D7:AH7,"A") | AO7: =SUM(AL7:AN7)
A8: 2 | B8: =IFERROR(VLOOKUP(A8&$AJ$2,Data!$A$2:$AM$131,3,FALSE), "") | C8: =IFERROR(VLOOKUP(A8&$AJ$2,Data!$A$2:$AM$131,4,FALSE), "") | AK8: I | AL8: =COUNTIF(D8:AH8,"S") | AM8: =COUNTIF(D8:AH8,"I") | AN8: =COUNTIF(D8:AH8,"A") | AO8: =SUM(AL8:AN8)
A9: 3 | B9: =IFERROR(VLOOKUP(A9&$AJ$2,Data!$A$2:$AM$131,3,FALSE), "") | C9: =IFERROR(VLOOKUP(A9&$AJ$2,Data!$A$2:$AM$131,4,FALSE), "") | AK9: A | AL9: =COUNTIF(D9:AH9,"S") | AM9: =COUNTIF(D9:AH9,"I") | AN9: =COUNTIF(D9:AH9,"A") | AO9: =SUM(AL9:AN9)
A10: 4 | AK10: . | AL10: =COUNTIF(D10:AH10,"S") | AM10: =COUNTIF(D10:AH10,"I") | AN10: =COUNTIF(D10:AH10,"A") | AO10: =SUM(AL10:AN10)
A11: 5 | B11: =IFERROR(VLOOKUP(A11&$AJ$2,Data!$A$2:$AM$131,3,FALSE), "") | C11: =IFERROR(VLOOKUP(A11&$AJ$2,Data!$A$2:$AM$131,4,FALSE), "") | AL11: =COUNTIF(D11:AH11,"S") | AM11: =COUNTIF(D11:AH11,"I") | AN11: =COUNTIF(D11:AH11,"A") | AO11: =SUM(AL11:AN11)
A12: 6 | B12: =IFERROR(VLOOKUP(A12&$AJ$2,Data!$A$2:$AM$131,3,FALSE), "") | C12: =IFERROR(VLOOKUP(A12&$AJ$2,Data!$A$2:$AM$131,4,FALSE), "") | D12: S | E12: S | AL12: =COUNTIF(D12:AH12,"S") | AM12: =COUNTIF(D12:AH12,"I") | AN12: =COUNTIF(D12:AH12,"A") | AO12: =SUM(AL12:AN12)
A13: 7 | B13: =IFERROR(VLOOKUP(A13&$AJ$2,Data!$A$2:$AM$131,3,FALSE), "") | C13: =IFERROR(VLOOKUP(A13&$AJ$2,Data!$A$2:$AM$131,4,FALSE), "") | P13: S | R13: S | AL13: =COUNTIF(D13:AH13,"S") | AM13: =COUNTIF(D13:AH13,"I") | AN13: =COUNTIF(D13:AH13,"A") | AO13: =SUM(AL13:AN13)
A14: 8 | B14: =IFERROR(VLOOKUP(A14&$AJ$2,Data!$A$2:$AM$131,3,FALSE), "") | C14: =IFERROR(VLOOKUP(A14&$AJ$2,Data!$A$2:$AM$131,4,FALSE), "") | D14: S | AL14: =COUNTIF(D14:AH14,"S") | AM14: =COUNTIF(D14:AH14,"I") | AN14: =COUNTIF(D14:AH14,"A") | AO14: =SUM(AL14:AN14)
A15: 9 | B15: =IFERROR(VLOOKUP(A15&$AJ$2,Data!$A$2:$AM$131,3,FALSE), "") | C15: =IFERROR(VLOOKUP(A15&$AJ$2,Data!$A$2:$AM$131,4,FALSE), "") | AL15: =COUNTIF(D15:AH15,"S") | AM15: =COUNTIF(D15:AH15,"I") | AN15: =COUNTIF(D15:AH15,"A") | AO15: =SUM(AL15:AN15)
A16: 10 | B16: =IFERROR(VLOOKUP(A16&$AJ$2,Data!$A$2:$AM$131,3,FALSE), "") | C16: =IFERROR(VLOOKUP(A16&$AJ$2,Data!$A$2:$AM$131,4,FALSE), "") | K16: . | L16: S | AL16: =COUNTIF(D16:AH16,"S") | AM16: =COUNTIF(D16:AH16,"I") | AN16: =COUNTIF(D16:AH16,"A") | AO16: =SUM(AL16:AN16)
A17: 11 | B17: =IFERROR(VLOOKUP(A17&$AJ$2,Data!$A$2:$AM$131,3,FALSE), "") | C17: =IFERROR(VLOOKUP(A17&$AJ$2,Data!$A$2:$AM$131,4,FALSE), "") | I17: S | J17: S | K17: S | L17: S | P17: S | Q17: S | R17: S | S17: S | AL17: =COUNTIF(D17:AH17,"S") | AM17: =COUNTIF(D17:AH17,"I") | AN17: =COUNTIF(D17:AH17,"A") | AO17: =SUM(AL17:AN17)
A18: 12 | B18: =IFERROR(VLOOKUP(A18&$AJ$2,Data!$A$2:$AM$131,3,FALSE), "") | C18: =IFERROR(VLOOKUP(A18&$AJ$2,Data!$A$2:$AM$131,4,FALSE), "") | AL18: =COUNTIF(D18:AH18,"S") | AM18: =COUNTIF(D18:AH18,"I") | AN18: =COUNTIF(D18:AH18,"A") | AO18: =SUM(AL18:AN18)
A19: 13 | B19: =IFERROR(VLOOKUP(A19&$AJ$2,Data!$A$2:$AM$131,3,FALSE), "") | C19: =IFERROR(VLOOKUP(A19&$AJ$2,Data!$A$2:$AM$131,4,FALSE), "") | AL19: =COUNTIF(D19:AH19,"S") | AM19: =COUNTIF(D19:AH19,"I") | AN19: =COUNTIF(D19:AH19,"A") | AO19: =SUM(AL19:AN19)
A20: 14 | B20: =IFERROR(VLOOKUP(A20&$AJ$2,Data!$A$2:$AM$131,3,FALSE), "") | C20: =IFERROR(VLOOKUP(A20&$AJ$2,Data!$A$2:$AM$131,4,FALSE), "") | AL20: =COUNTIF(D20:AH20,"S") | AM20: =COUNTIF(D20:AH20,"I") | AN20: =COUNTIF(D20:AH20,"A") | AO20: =SUM(AL20:AN20)
A21: 15 | B21: =IFERROR(VLOOKUP(A21&$AJ$2,Data!$A$2:$AM$131,3,FALSE), "") | C21: =IFERROR(VLOOKUP(A21&$AJ$2,Data!$A$2:$AM$131,4,FALSE), "") | AL21: =COUNTIF(D21:AH21,"S") | AM21: =COUNTIF(D21:AH21,"I") | AN21: =COUNTIF(D21:AH21,"A") | AO21: =SUM(AL21:AN21)
A22: 16 | B22: =IFERROR(VLOOKUP(A22&$AJ$2,Data!$A$2:$AM$131,3,FALSE), "") | C22: =IFERROR(VLOOKUP(A22&$AJ$2,Data!$A$2:$AM$131,4,FALSE), "") | AL22: =COUNTIF(D22:AH22,"S") | AM22: =COUNTIF(D22:AH22,"I") | AN22: =COUNTIF(D22:AH22,"A") | AO22: =SUM(AL22:AN22)
A23: 17 | B23: =IFERROR(VLOOKUP(A23&$AJ$2,Data!$A$2:$AM$131,3,FALSE), "") | C23: =IFERROR(VLOOKUP(A23&$AJ$2,Data!$A$2:$AM$131,4,FALSE), "") | AL23: =COUNTIF(D23:AH23,"S") | AM23: =COUNTIF(D23:AH23,"I") | AN23: =COUNTIF(D23:AH23,"A") | AO23: =SUM(AL23:AN23)
A24: 18 | B24: =IFERROR(VLOOKUP(A24&$AJ$2,Data!$A$2:$AM$131,3,FALSE), "") | C24: =IFERROR(VLOOKUP(A24&$AJ$2,Data!$A$2:$AM$131,4,FALSE), "") | AL24: =COUNTIF(D24:AH24,"S") | AM24: =COUNTIF(D24:AH24,"I") | AN24: =COUNTIF(D24:AH24,"A") | AO24: =SUM(AL24:AN24)
A25: 19 | B25: =IFERROR(VLOOKUP(A25&$AJ$2,Data!$A$2:$AM$131,3,FALSE), "") | C25: =IFERROR(VLOOKUP(A25&$AJ$2,Data!$A$2:$AM$131,4,FALSE), "") | AL25: =COUNTIF(D25:AH25,"S") | AM25: =COUNTIF(D25:AH25,"I") | AN25: =COUNTIF(D25:AH25,"A") | AO25: =SUM(AL25:AN25)
A26: 20 | B26: =IFERROR(VLOOKUP(A26&$AJ$2,Data!$A$2:$AM$131,3,FALSE), "") | C26: =IFERROR(VLOOKUP(A26&$AJ$2,Data!$A$2:$AM$131,4,FALSE), "") | AL26: =COUNTIF(D26:AH26,"S") | AM26: =COUNTIF(D26:AH26,"I") | AN26: =COUNTIF(D26:AH26,"A") | AO26: =SUM(AL26:AN26)
A27: 21 | B27: =IFERROR(VLOOKUP(A27&$AJ$2,Data!$A$2:$AM$131,3,FALSE), "") | C27: =IFERROR(VLOOKUP(A27&$AJ$2,Data!$A$2:$AM$131,4,FALSE), "") | AL27: =COUNTIF(D27:AH27,"S") | AM27: =COUNTIF(D27:AH27,"I") | AN27: =COUNTIF(D27:AH27,"A") | AO27: =SUM(AL27:AN27)
A28: 22 | B28: =IFERROR(VLOOKUP(A28&$AJ$2,Data!$A$2:$AM$131,3,FALSE), "") | C28: =IFERROR(VLOOKUP(A28&$AJ$2,Data!$A$2:$AM$131,4,FALSE), "") | AL28: =COUNTIF(D28:AH28,"S") | AM28: =COUNTIF(D28:AH28,"I") | AN28: =COUNTIF(D28:AH28,"A") | AO28: =SUM(AL28:AN28)
A29: 23 | B29: =IFERROR(VLOOKUP(A29&$AJ$2,Data!$A$2:$AM$131,3,FALSE), "") | C29: =IFERROR(VLOOKUP(A29&$AJ$2,Data!$A$2:$AM$131,4,FALSE), "") | AL29: =COUNTIF(D29:AH29,"S") | AM29: =COUNTIF(D29:AH29,"I") | AN29: =COUNTIF(D29:AH29,"A") | AO29: =SUM(AL29:AN29)
... A46: 40 | B46: =IFERROR(VLOOKUP(A46&$AJ$2,Data!$A$2:$AM$131,3,FALSE), "") | C46: =IFERROR(VLOOKUP(A46&$AJ$2,Data!$A$2:$AM$131,4,FALSE), "") | AL46: =COUNTIF(D46:AH46,"S") | AM46: =COUNTIF(D46:AH46,"I") | AN46: =COUNTIF(D46:AH46,"A") | AO46: =SUM(AL46:AN46)
C48: S | E48: =COUNTIF(E7:E46,"S") | F48: =COUNTIF(F7:F46,"S") | G48: =COUNTIF(G7:G46,"S") | H48: =COUNTIF(H7:H46,"S") | I48: =COUNTIF(I7:I46,"S") | J48: =COUNTIF(J7:J46,"S") | K48: =COUNTIF(K7:K46,"S") | L48: =COUNTIF(L7:L46,"S") | ... AH48: =COUNTIF(AH7:AH46,"S")
C49: I | E49: =COUNTIF(E7:E46,"I") | F49: =COUNTIF(F7:F46,"I") | G49: =COUNTIF(G7:G46,"I") | H49: =COUNTIF(H7:H46,"I") | I49: =COUNTIF(I7:I46,"I") | J49: =COUNTIF(J7:J46,"I") | K49: =COUNTIF(K7:K46,"I") | L49: =COUNTIF(L7:L46,"I") | ... AH49: =COUNTIF(AH7:AH46,"I")
C50: A | E50: =COUNTIF(E7:E46,"A") | F50: =COUNTIF(F7:F46,"A") | G50: =COUNTIF(G7:G46,"A") | H50: =COUNTIF(H7:H46,"A") | I50: =COUNTIF(I7:I46,"A") | J50: =COUNTIF(J7:J46,"A") | K50: =COUNTIF(K7:K46,"A") | L50: =COUNTIF(L7:L46,"A") | ... AH50: =COUNTIF(AH7:AH46,"A")

Sheet TKa
A1: 0
A2: DAFTAR NAMA MURID T.P. 2025/2026 | AJ2: TKA
A3: Kelas | C3: =" : " & IF(AJ2="","",AJ2)
A4: Walikelas | C4: =IFERROR(" : " &VLOOKUP($A$7&$AJ$2,#REF!,6,FALSE), "")
A5: Nomor | C5: Nama | D5: April
A6: Urt | B6: Induk | D6: 1 | E6: 2 | F6: 3 | G6: 4 | H6: 5 | I6: 6 | J6: 7 | K6: M | L6: 9 | M6: 10 | N6: 11 | O6: 12 | P6: 13 | Q6: 14 | R6: 15 | S6: 16 | T6: 17 | U6: 18 | V6: 19 | W6: 20 | X6: 21 | Y6: 22 | Z6: 23 | AA6: 24 | AB6: 25 | AC6: 26 | AD6: 27 | AE6: 28 | AF6: 29 | AG6: 30 | AH6: 31 | AL6: S | AM6: I | AN6: A | AO6: Total
A7: 1 | B7: =IFERROR(VLOOKUP(A7&$AJ$2,Data!$A$2:$AM$131,3,FALSE), "") | C7: =IFERROR(VLOOKUP(A7&$AJ$2,Data!$A$2:$AM$131,4,FALSE), "") | D7: S | E7: S | I7: S | J7: S | K7: S | L7: S | P7: S | Q7: S | R7: S | S7: S | AK7: S | AL7: =COUNTIF(D7:AH7,"S") | AM7: =COUNTIF(D7:AH7,"I") | AN7: =COUNTIF(D7:AH7,"A") | AO7: =SUM(AL7:AN7)
A8: 2 | B8: =IFERROR(VLOOKUP(A8&$AJ$2,Data!$A$2:$AM$131,3,FALSE), "") | C8: =IFERROR(VLOOKUP(A8&$AJ$2,Data!$A$2:$AM$131,4,FALSE), "") | AK8: I | AL8: =COUNTIF(D8:AH8,"S") | AM8: =COUNTIF(D8:AH8,"I") | AN8: =COUNTIF(D8:AH8,"A") | AO8: =SUM(AL8:AN8)
A9: 3 | B9: =IFERROR(VLOOKUP(A9&$AJ$2,Data!$A$2:$AM$131,3,FALSE), "") | C9: =IFERROR(VLOOKUP(A9&$AJ$2,Data!$A$2:$AM$131,4,FALSE), "") | L9: S | AK9: A | AL9: =COUNTIF(D9:AH9,"S") | AM9: =COUNTIF(D9:AH9,"I") | AN9: =COUNTIF(D9:AH9,"A") | AO9: =SUM(AL9:AN9)
A10: 4 | B10: =IFERROR(VLOOKUP(A10&$AJ$2,Data!$A$2:$AM$131,3,FALSE), "") | C10: =IFERROR(VLOOKUP(A10&$AJ$2,Data!$A$2:$AM$131,4,FALSE), "") | AK10: . | AL10: =COUNTIF(D10:AH10,"S") | AM10: =COUNTIF(D10:AH10,"I") | AN10: =COUNTIF(D10:AH10,"A") | AO10: =SUM(AL10:AN10)
A11: 5 | B11: =IFERROR(VLOOKUP(A11&$AJ$2,Data!$A$2:$AM$131,3,FALSE), "") | C11: =IFERROR(VLOOKUP(A11&$AJ$2,Data!$A$2:$AM$131,4,FALSE), "") | D11: I | E11: I | I11: I | J11: I | AL11: =COUNTIF(D11:AH11,"S") | AM11: =COUNTIF(D11:AH11,"I") | AN11: =COUNTIF(D11:AH11,"A") | AO11: =SUM(AL11:AN11)
A12: 6 | B12: =IFERROR(VLOOKUP(A12&$AJ$2,Data!$A$2:$AM$131,3,FALSE), "") | C12: =IFERROR(VLOOKUP(A12&$AJ$2,Data!$A$2:$AM$131,4,FALSE), "") | E12: . | AL12: =COUNTIF(D12:AH12,"S") | AM12: =COUNTIF(D12:AH12,"I") | AN12: =COUNTIF(D12:AH12,"A") | AO12: =SUM(AL12:AN12)
A13: 7 | B13: =IFERROR(VLOOKUP(A13&$AJ$2,Data!$A$2:$AM$131,3,FALSE), "") | C13: =IFERROR(VLOOKUP(A13&$AJ$2,Data!$A$2:$AM$131,4,FALSE), "") | P13: S | Q13: S | R13: S | S13: S | AL13: =COUNTIF(D13:AH13,"S") | AM13: =COUNTIF(D13:AH13,"I") | AN13: =COUNTIF(D13:AH13,"A") | AO13: =SUM(AL13:AN13)
A14: 8 | B14: =IFERROR(VLOOKUP(A14&$AJ$2,Data!$A$2:$AM$131,3,FALSE), "") | C14: =IFERROR(VLOOKUP(A14&$AJ$2,Data!$A$2:$AM$131,4,FALSE), "") | AL14: =COUNTIF(D14:AH14,"S") | AM14: =COUNTIF(D14:AH14,"I") | AN14: =COUNTIF(D14:AH14,"A") | AO14: =SUM(AL14:AN14)
A15: 9 | B15: =IFERROR(VLOOKUP(A15&$AJ$2,Data!$A$2:$AM$131,3,FALSE), "") | C15: =IFERROR(VLOOKUP(A15&$AJ$2,Data!$A$2:$AM$131,4,FALSE), "") | AL15: =COUNTIF(D15:AH15,"S") | AM15: =COUNTIF(D15:AH15,"I") | AN15: =COUNTIF(D15:AH15,"A") | AO15: =SUM(AL15:AN15)
A16: 10 | B16: =IFERROR(VLOOKUP(A16&$AJ$2,Data!$A$2:$AM$131,3,FALSE), "") | C16: =IFERROR(VLOOKUP(A16&$AJ$2,Data!$A$2:$AM$131,4,FALSE), "") | AL16: =COUNTIF(D16:AH16,"S") | AM16: =COUNTIF(D16:AH16,"I") | AN16: =COUNTIF(D16:AH16,"A") | AO16: =SUM(AL16:AN16)
A17: 11 | B17: =IFERROR(VLOOKUP(A17&$AJ$2,Data!$A$2:$AM$131,3,FALSE), "") | C17: =IFERROR(VLOOKUP(A17&$AJ$2,Data!$A$2:$AM$131,4,FALSE), "") | AL17: =COUNTIF(D17:AH17,"S") | AM17: =COUNTIF(D17:AH17,"I") | AN17: =COUNTIF(D17:AH17,"A") | AO17: =SUM(AL17:AN17)
A18: 12 | B18: =IFERROR(VLOOKUP(A18&$AJ$2,Data!$A$2:$AM$131,3,FALSE), "") | C18: =IFERROR(VLOOKUP(A18&$AJ$2,Data!$A$2:$AM$131,4,FALSE), "") | AL18: =COUNTIF(D18:AH18,"S") | AM18: =COUNTIF(D18:AH18,"I") | AN18: =COUNTIF(D18:AH18,"A") | AO18: =SUM(AL18:AN18)
A19: 13 | B19: =IFERROR(VLOOKUP(A19&$AJ$2,Data!$A$2:$AM$131,3,FALSE), "") | C19: =IFERROR(VLOOKUP(A19&$AJ$2,Data!$A$2:$AM$131,4,FALSE), "") | AL19: =COUNTIF(D19:AH19,"S") | AM19: =COUNTIF(D19:AH19,"I") | AN19: =COUNTIF(D19:AH19,"A") | AO19: =SUM(AL19:AN19)
A20: 14 | B20: =IFERROR(VLOOKUP(A20&$AJ$2,Data!$A$2:$AM$131,3,FALSE), "") | C20: =IFERROR(VLOOKUP(A20&$AJ$2,Data!$A$2:$AM$131,4,FALSE), "") | AL20: =COUNTIF(D20:AH20,"S") | AM20: =COUNTIF(D20:AH20,"I") | AN20: =COUNTIF(D20:AH20,"A") | AO20: =SUM(AL20:AN20)
A21: 15 | B21: =IFERROR(VLOOKUP(A21&$AJ$2,Data!$A$2:$AM$131,3,FALSE), "") | C21: =IFERROR(VLOOKUP(A21&$AJ$2,Data!$A$2:$AM$131,4,FALSE), "") | L21: S | AL21: =COUNTIF(D21:AH21,"S") | AM21: =COUNTIF(D21:AH21,"I") | AN21: =COUNTIF(D21:AH21,"A") | AO21: =SUM(AL21:AN21)
A22: 16 | B22: =IFERROR(VLOOKUP(A22&$AJ$2,Data!$A$2:$AM$131,3,FALSE), "") | C22: =IFERROR(VLOOKUP(A22&$AJ$2,Data!$A$2:$AM$131,4,FALSE), "") | J22: . | AL22: =COUNTIF(D22:AH22,"S") | AM22: =COUNTIF(D22:AH22,"I") | AN22: =COUNTIF(D22:AH22,"A") | AO22: =SUM(AL22:AN22)
A23: 17 | B23: =IFERROR(VLOOKUP(A23&$AJ$2,Data!$A$2:$AM$131,3,FALSE), "") | C23: =IFERROR(VLOOKUP(A23&$AJ$2,Data!$A$2:$AM$131,4,FALSE), "") | J23: I | P23: S | Q23: S | R23: S | S23: S | AL23: =COUNTIF(D23:AH23,"S") | AM23: =COUNTIF(D23:AH23,"I") | AN23: =COUNTIF(D23:AH23,"A") | AO23: =SUM(AL23:AN23)
A24: 18 | B24: =IFERROR(VLOOKUP(A24&$AJ$2,Data!$A$2:$AM$131,3,FALSE), "") | C24: =IFERROR(VLOOKUP(A24&$AJ$2,Data!$A$2:$AM$131,4,FALSE), "") | AL24: =COUNTIF(D24:AH24,"S") | AM24: =COUNTIF(D24:AH24,"I") | AN24: =COUNTIF(D24:AH24,"A") | AO24: =SUM(AL24:AN24)
A25: 19 | B25: =IFERROR(VLOOKUP(A25&$AJ$2,Data!$A$2:$AM$131,3,FALSE), "") | C25: =IFERROR(VLOOKUP(A25&$AJ$2,Data!$A$2:$AM$131,4,FALSE), "") | AL25: =COUNTIF(D25:AH25,"S") | AM25: =COUNTIF(D25:AH25,"I") | AN25: =COUNTIF(D25:AH25,"A") | AO25: =SUM(AL25:AN25)
A26: 20 | B26: =IFERROR(VLOOKUP(A26&$AJ$2,Data!$A$2:$AM$131,3,FALSE), "") | C26: =IFERROR(VLOOKUP(A26&$AJ$2,Data!$A$2:$AM$131,4,FALSE), "") | AL26: =COUNTIF(D26:AH26,"S") | AM26: =COUNTIF(D26:AH26,"I") | AN26: =COUNTIF(D26:AH26,"A") | AO26: =SUM(AL26:AN26)
A27: 21 | B27: =IFERROR(VLOOKUP(A27&$AJ$2,Data!$A$2:$AM$131,3,FALSE), "") | C27: =IFERROR(VLOOKUP(A27&$AJ$2,Data!$A$2:$AM$131,4,FALSE), "") | AL27: =COUNTIF(D27:AH27,"S") | AM27: =COUNTIF(D27:AH27,"I") | AN27: =COUNTIF(D27:AH27,"A") | AO27: =SUM(AL27:AN27)
A28: 22 | B28: =IFERROR(VLOOKUP(A28&$AJ$2,Data!$A$2:$AM$131,3,FALSE), "") | C28: =IFERROR(VLOOKUP(A28&$AJ$2,Data!$A$2:$AM$131,4,FALSE), "") | AL28: =COUNTIF(D28:AH28,"S") | AM28: =COUNTIF(D28:AH28,"I") | AN28: =COUNTIF(D28:AH28,"A") | AO28: =SUM(AL28:AN28)
A29: 23 | B29: =IFERROR(VLOOKUP(A29&$AJ$2,Data!$A$2:$AM$131,3,FALSE), "") | C29: =IFERROR(VLOOKUP(A29&$AJ$2,Data!$A$2:$AM$131,4,FALSE), "") | K29: S | L29: S | AL29: =COUNTIF(D29:AH29,"S") | AM29: =COUNTIF(D29:AH29,"I") | AN29: =COUNTIF(D29:AH29,"A") | AO29: =SUM(AL29:AN29)
A30: 24 | B30: =IFERROR(VLOOKUP(A30&$AJ$2,Data!$A$2:$AM$131,3,FALSE), "") | C30: =IFERROR(VLOOKUP(A30&$AJ$2,Data!$A$2:$AM$131,4,FALSE), "") | AL30: =COUNTIF(D30:AH30,"S") | AM30: =COUNTIF(D30:AH30,"I") | AN30: =COUNTIF(D30:AH30,"A") | AO30: =SUM(AL30:AN30)
A31: 25 | B31: =IFERROR(VLOOKUP(A31&$AJ$2,Data!$A$2:$AM$131,3,FALSE), "") | C31: =IFERROR(VLOOKUP(A31&$AJ$2,Data!$A$2:$AM$131,4,FALSE), "") | P31: S | Q31: S | R31: S | S31: S | AL31: =COUNTIF(D31:AH31,"S") | AM31: =COUNTIF(D31:AH31,"I") | AN31: =COUNTIF(D31:AH31,"A") | AO31: =SUM(AL31:AN31)
A32: 26 | B32: =IFERROR(VLOOKUP(A32&$AJ$2,Data!$A$2:$AM$131,3,FALSE), "") | C32: =IFERROR(VLOOKUP(A32&$AJ$2,Data!$A$2:$AM$131,4,FALSE), "") | AL32: =COUNTIF(D32:AH32,"S") | AM32: =COUNTIF(D32:AH32,"I") | AN32: =COUNTIF(D32:AH32,"A") | AO32: =SUM(AL32:AN32)
A33: 27 | B33: =IFERROR(VLOOKUP(A33&$AJ$2,Data!$A$2:$AM$131,3,FALSE), "") | C33: =IFERROR(VLOOKUP(A33&$AJ$2,Data!$A$2:$AM$131,4,FALSE), "") | AL33: =COUNTIF(D33:AH33,"S") | AM33: =COUNTIF(D33:AH33,"I") | AN33: =COUNTIF(D33:AH33,"A") | AO33: =SUM(AL33:AN33)
A34: 28 | B34: =IFERROR(VLOOKUP(A34&$AJ$2,Data!$A$2:$AM$131,3,FALSE), "") | C34: =IFERROR(VLOOKUP(A34&$AJ$2,Data!$A$2:$AM$131,4,FALSE), "") | AL34: =COUNTIF(D34:AH34,"S") | AM34: =COUNTIF(D34:AH34,"I") | AN34: =COUNTIF(D34:AH34,"A") | AO34: =SUM(AL34:AN34)
A35: 29 | B35: =IFERROR(VLOOKUP(A35&$AJ$2,Data!$A$2:$AM$131,3,FALSE), "") | C35: =IFERROR(VLOOKUP(A35&$AJ$2,Data!$A$2:$AM$131,4,FALSE), "") | AL35: =COUNTIF(D35:AH35,"S") | AM35: =COUNTIF(D35:AH35,"I") | AN35: =COUNTIF(D35:AH35,"A") | AO35: =SUM(AL35:AN35)
A36: 30 | B36: =IFERROR(VLOOKUP(A36&$AJ$2,Data!$A$2:$AM$131,3,FALSE), "") | C36: =IFERROR(VLOOKUP(A36&$AJ$2,Data!$A$2:$AM$131,4,FALSE), "") | AL36: =COUNTIF(D36:AH36,"S") | AM36: =COUNTIF(D36:AH36,"I") | AN36: =COUNTIF(D36:AH36,"A") | AO36: =SUM(AL36:AN36)
A37: 31 | B37: =IFERROR(VLOOKUP(A37&$AJ$2,Data!$A$2:$AM$131,3,FALSE), "") | C37: =IFERROR(VLOOKUP(A37&$AJ$2,Data!$A$2:$AM$131,4,FALSE), "") | AL37: =COUNTIF(D37:AH37,"S") | AM37: =COUNTIF(D37:AH37,"I") | AN37: =COUNTIF(D37:AH37,"A") | AO37: =SUM(AL37:AN37)
A38: 32 | B38: =IFERROR(VLOOKUP(A38&$AJ$2,Data!$A$2:$AM$131,3,FALSE), "") | C38: =IFERROR(VLOOKUP(A38&$AJ$2,Data!$A$2:$AM$131,4,FALSE), "") | AL38: =COUNTIF(D38:AH38,"S") | AM38: =COUNTIF(D38:AH38,"I") | AN38: =COUNTIF(D38:AH38,"A") | AO38: =SUM(AL38:AN38)
A39: 33 | B39: =IFERROR(VLOOKUP(A39&$AJ$2,Data!$A$2:$AM$131,3,FALSE), "") | C39: =IFERROR(VLOOKUP(A39&$AJ$2,Data!$A$2:$AM$131,4,FALSE), "") | AL39: =COUNTIF(D39:AH39,"S") | AM39: =COUNTIF(D39:AH39,"I") | AN39: =COUNTIF(D39:AH39,"A") | AO39: =SUM(AL39:AN39)
A40: 34 | B40: =IFERROR(VLOOKUP(A40&$AJ$2,Data!$A$2:$AM$131,3,FALSE), "") | C40: =IFERROR(VLOOKUP(A40&$AJ$2,Data!$A$2:$AM$131,4,FALSE), "") | AL40: =COUNTIF(D40:AH40,"S") | AM40: =COUNTIF(D40:AH40,"I") | AN40: =COUNTIF(D40:AH40,"A") | AO40: =SUM(AL40:AN40)
...

Sheet TKB1
A1: 0 | S1: 0
A2: DAFTAR NAMA MURID T.P. 2025/2026 | AJ2: TKB1
A3: Kelas | C3: =" : " & IF(AJ2="","",AJ2)
A4: Walikelas | C4: =IFERROR(" : " &VLOOKUP($A$7&$AJ$2,#REF!,6,FALSE), "")
A5: Nomor | C5: Nama | D5: April
A6: Urt | B6: Induk | D6: 1 | E6: 2 | F6: 3 | G6: 4 | H6: 5 | I6: 6 | J6: M | K6: 8 | L6: 9 | M6: 10 | N6: 11 | O6: 12 | P6: 13 | Q6: 14 | R6: 15 | S6: 16 | T6: 17 | U6: 18 | V6: 19 | W6: 20 | X6: 21 | Y6: 22 | Z6: 23 | AA6: 24 | AB6: 25 | AC6: 26 | AD6: 27 | AE6: 28 | AF6: 29 | AG6: 30 | AH6: 31 | AL6: S | AM6: I | AN6: A | AO6: Total
A7: 1 | B7: =IFERROR(VLOOKUP(A7&$AJ$2,Data!$A$2:$AM$131,3,FALSE), "") | C7: =IFERROR(VLOOKUP(A7&$AJ$2,Data!$A$2:$AM$131,4,FALSE), "") | D7: I | E7: I | AK7: S | AL7: =COUNTIF(D7:AH7,"S") | AM7: =COUNTIF(D7:AH7,"I") | AN7: =COUNTIF(D7:AH7,"A") | AO7: =SUM(AL7:AN7)
A8: 2 | B8: =IFERROR(VLOOKUP(A8&$AJ$2,Data!$A$2:$AM$131,3,FALSE), "") | C8: =IFERROR(VLOOKUP(A8&$AJ$2,Data!$A$2:$AM$131,4,FALSE), "") | AK8: I | AL8: =COUNTIF(D8:AH8,"S") | AM8: =COUNTIF(D8:AH8,"I") | AN8: =COUNTIF(D8:AH8,"A") | AO8: =SUM(AL8:AN8)
A9: 3 | B9: =IFERROR(VLOOKUP(A9&$AJ$2,Data!$A$2:$AM$131,3,FALSE), "") | C9: =IFERROR(VLOOKUP(A9&$AJ$2,Data!$A$2:$AM$131,4,FALSE), "") | AK9: A | AL9: =COUNTIF(D9:AH9,"S") | AM9: =COUNTIF(D9:AH9,"I") | AN9: =COUNTIF(D9:AH9,"A") | AO9: =SUM(AL9:AN9)
A10: 4 | B10: =IFERROR(VLOOKUP(A10&$AJ$2,Data!$A$2:$AM$131,3,FALSE), "") | C10: =IFERROR(VLOOKUP(A10&$AJ$2,Data!$A$2:$AM$131,4,FALSE), "") | AK10: . | AL10: =COUNTIF(D10:AH10,"S") | AM10: =COUNTIF(D10:AH10,"I") | AN10: =COUNTIF(D10:AH10,"A") | AO10: =SUM(AL10:AN10)
A11: 5 | B11: =IFERROR(VLOOKUP(A11&$AJ$2,Data!$A$2:$AM$131,3,FALSE), "") | C11: =IFERROR(VLOOKUP(A11&$AJ$2,Data!$A$2:$AM$131,4,FALSE), "") | AL11: =COUNTIF(D11:AH11,"S") | AM11: =COUNTIF(D11:AH11,"I") | AN11: =COUNTIF(D11:AH11,"A") | AO11: =SUM(AL11:AN11)
A12: 6 | B12: =IFERROR(VLOOKUP(A12&$AJ$2,Data!$A$2:$AM$131,3,FALSE), "") | C12: =IFERROR(VLOOKUP(A12&$AJ$2,Data!$A$2:$AM$131,4,FALSE), "") | AL12: =COUNTIF(D12:AH12,"S") | AM12: =COUNTIF(D12:AH12,"I") | AN12: =COUNTIF(D12:AH12,"A") | AO12: =SUM(AL12:AN12)
A13: 7 | B13: =IFERROR(VLOOKUP(A13&$AJ$2,Data!$A$2:$AM$131,3,FALSE), "") | C13: =IFERROR(VLOOKUP(A13&$AJ$2,Data!$A$2:$AM$131,4,FALSE), "") | AL13: =COUNTIF(D13:AH13,"S") | AM13: =COUNTIF(D13:AH13,"I") | AN13: =COUNTIF(D13:AH13,"A") | AO13: =SUM(AL13:AN13)
A14: 8 | B14: =IFERROR(VLOOKUP(A14&$AJ$2,Data!$A$2:$AM$131,3,FALSE), "") | C14: =IFERROR(VLOOKUP(A14&$AJ$2,Data!$A$2:$AM$131,4,FALSE), "") | AL14: =COUNTIF(D14:AH14,"S") | AM14: =COUNTIF(D14:AH14,"I") | AN14: =COUNTIF(D14:AH14,"A") | AO14: =SUM(AL14:AN14)
A15: 9 | B15: =IFERROR(VLOOKUP(A15&$AJ$2,Data!$A$2:$AM$131,3,FALSE), "") | C15: =IFERROR(VLOOKUP(A15&$AJ$2,Data!$A$2:$AM$131,4,FALSE), "") | AL15: =COUNTIF(D15:AH15,"S") | AM15: =COUNTIF(D15:AH15,"I") | AN15: =COUNTIF(D15:AH15,"A") | AO15: =SUM(AL15:AN15)
A16: 10 | B16: =IFERROR(VLOOKUP(A16&$AJ$2,Data!$A$2:$AM$131,3,FALSE), "") | C16: =IFERROR(VLOOKUP(A16&$AJ$2,Data!$A$2:$AM$131,4,FALSE), "") | AL16: =COUNTIF(D16:AH16,"S") | AM16: =COUNTIF(D16:AH16,"I") | AN16: =COUNTIF(D16:AH16,"A") | AO16: =SUM(AL16:AN16)
A17: 11 | B17: =IFERROR(VLOOKUP(A17&$AJ$2,Data!$A$2:$AM$131,3,FALSE), "") | C17: =IFERROR(VLOOKUP(A17&$AJ$2,Data!$A$2:$AM$131,4,FALSE), "") | AL17: =COUNTIF(D17:AH17,"S") | AM17: =COUNTIF(D17:AH17,"I") | AN17: =COUNTIF(D17:AH17,"A") | AO17: =SUM(AL17:AN17)
A18: 12 | B18: =IFERROR(VLOOKUP(A18&$AJ$2,Data!$A$2:$AM$131,3,FALSE), "") | C18: =IFERROR(VLOOKUP(A18&$AJ$2,Data!$A$2:$AM$131,4,FALSE), "") | AL18: =COUNTIF(D18:AH18,"S") | AM18: =COUNTIF(D18:AH18,"I") | AN18: =COUNTIF(D18:AH18,"A") | AO18: =SUM(AL18:AN18)
A19: 13 | B19: =IFERROR(VLOOKUP(A19&$AJ$2,Data!$A$2:$AM$131,3,FALSE), "") | C19: =IFERROR(VLOOKUP(A19&$AJ$2,Data!$A$2:$AM$131,4,FALSE), "") | AL19: =COUNTIF(D19:AH19,"S") | AM19: =COUNTIF(D19:AH19,"I") | AN19: =COUNTIF(D19:AH19,"A") | AO19: =SUM(AL19:AN19)
A20: 14 | B20: =IFERROR(VLOOKUP(A20&$AJ$2,Data!$A$2:$AM$131,3,FALSE), "") | C20: =IFERROR(VLOOKUP(A20&$AJ$2,Data!$A$2:$AM$131,4,FALSE), "") | AL20: =COUNTIF(D20:AH20,"S") | AM20: =COUNTIF(D20:AH20,"I") | AN20: =COUNTIF(D20:AH20,"A") | AO20: =SUM(AL20:AN20)
A21: 15 | B21: =IFERROR(VLOOKUP(A21&$AJ$2,Data!$A$2:$AM$131,3,FALSE), "") | C21: =IFERROR(VLOOKUP(A21&$AJ$2,Data!$A$2:$AM$131,4,FALSE), "") | AL21: =COUNTIF(D21:AH21,"S") | AM21: =COUNTIF(D21:AH21,"I") | AN21: =COUNTIF(D21:AH21,"A") | AO21: =SUM(AL21:AN21)
A22: 16 | B22: =IFERROR(VLOOKUP(A22&$AJ$2,Data!$A$2:$AM$131,3,FALSE), "") | C22: =IFERROR(VLOOKUP(A22&$AJ$2,Data!$A$2:$AM$131,4,FALSE), "") | D22: S | AL22: =COUNTIF(D22:AH22,"S") | AM22: =COUNTIF(D22:AH22,"I") | AN22: =COUNTIF(D22:AH22,"A") | AO22: =SUM(AL22:AN22)
A23: 17 | B23: =IFERROR(VLOOKUP(A23&$AJ$2,Data!$A$2:$AM$131,3,FALSE), "") | C23: =IFERROR(VLOOKUP(A23&$AJ$2,Data!$A$2:$AM$131,4,FALSE), "") | I23: I | J23: I | AL23: =COUNTIF(D23:AH23,"S") | AM23: =COUNTIF(D23:AH23,"I") | AN23: =COUNTIF(D23:AH23,"A") | AO23: =SUM(AL23:AN23)
A24: 18 | B24: =IFERROR(VLOOKUP(A24&$AJ$2,Data!$A$2:$AM$131,3,FALSE), "") | C24: =IFERROR(VLOOKUP(A24&$AJ$2,Data!$A$2:$AM$131,4,FALSE), "") | I24: S | J24: S | AL24: =COUNTIF(D24:AH24,"S") | AM24: =COUNTIF(D24:AH24,"I") | AN24: =COUNTIF(D24:AH24,"A") | AO24: =SUM(AL24:AN24)
A25: 19 | B25: =IFERROR(VLOOKUP(A25&$AJ$2,Data!$A$2:$AM$131,3,FALSE), "") | C25: =IFERROR(VLOOKUP(A25&$AJ$2,Data!$A$2:$AM$131,4,FALSE), "") | D25: I | AL25: =COUNTIF(D25:AH25,"S") | AM25: =COUNTIF(D25:AH25,"I") | AN25: =COUNTIF(D25:AH25,"A") | AO25: =SUM(AL25:AN25)
A26: 20 | B26: =IFERROR(VLOOKUP(A26&$AJ$2,Data!$A$2:$AM$131,3,FALSE), "") | C26: =IFERROR(VLOOKUP(A26&$AJ$2,Data!$A$2:$AM$131,4,FALSE), "") | AL26: =COUNTIF(D26:AH26,"S") | AM26: =COUNTIF(D26:AH26,"I") | AN26: =COUNTIF(D26:AH26,"A") | AO26: =SUM(AL26:AN26)
A27: 21 | B27: =IFERROR(VLOOKUP(A27&$AJ$2,Data!$A$2:$AM$131,3,FALSE), "") | C27: =IFERROR(VLOOKUP(A27&$AJ$2,Data!$A$2:$AM$131,4,FALSE), "") | AL27: =COUNTIF(D27:AH27,"S") | AM27: =COUNTIF(D27:AH27,"I") | AN27: =COUNTIF(D27:AH27,"A") | AO27: =SUM(AL27:AN27)
A28: 22 | B28: =IFERROR(VLOOKUP(A28&$AJ$2,Data!$A$2:$AM$131,3,FALSE), "") | C28: =IFERROR(VLOOKUP(A28&$AJ$2,Data!$A$2:$AM$131,4,FALSE), "") | AL28: =COUNTIF(D28:AH28,"S") | AM28: =COUNTIF(D28:AH28,"I") | AN28: =COUNTIF(D28:AH28,"A") | AO28: =SUM(AL28:AN28)
A29: 23 | B29: =IFERROR(VLOOKUP(A29&$AJ$2,Data!$A$2:$AM$131,3,FALSE), "") | C29: =IFERROR(VLOOKUP(A29&$AJ$2,Data!$A$2:$AM$131,4,FALSE), "") | AL29: =COUNTIF(D29:AH29,"S") | AM29: =COUNTIF(D29:AH29,"I") | AN29: =COUNTIF(D29:AH29,"A") | AO29: =SUM(AL29:AN29)
A30: 24 | B30: =IFERROR(VLOOKUP(A30&$AJ$2,Data!$A$2:$AM$131,3,FALSE), "") | C30: =IFERROR(VLOOKUP(A30&$AJ$2,Data!$A$2:$AM$131,4,FALSE), "") | AL30: =COUNTIF(D30:AH30,"S") | AM30: =COUNTIF(D30:AH30,"I") | AN30: =COUNTIF(D30:AH30,"A") | AO30: =SUM(AL30:AN30)
A31: 25 | B31: =IFERROR(VLOOKUP(A31&$AJ$2,Data!$A$2:$AM$131,3,FALSE), "") | C31: =IFERROR(VLOOKUP(A31&$AJ$2,Data!$A$2:$AM$131,4,FALSE), "") | AL31: =COUNTIF(D31:AH31,"S") | AM31: =COUNTIF(D31:AH31,"I") | AN31: =COUNTIF(D31:AH31,"A") | AO31: =SUM(AL31:AN31)
A32: 26 | B32: =IFERROR(VLOOKUP(A32&$AJ$2,Data!$A$2:$AM$131,3,FALSE), "") | C32: =IFERROR(VLOOKUP(A32&$AJ$2,Data!$A$2:$AM$131,4,FALSE), "") | AL32: =COUNTIF(D32:AH32,"S") | AM32: =COUNTIF(D32:AH32,"I") | AN32: =COUNTIF(D32:AH32,"A") | AO32: =SUM(AL32:AN32)
A33: 27 | B33: =IFERROR(VLOOKUP(A33&$AJ$2,Data!$A$2:$AM$131,3,FALSE), "") | C33: =IFERROR(VLOOKUP(A33&$AJ$2,Data!$A$2:$AM$131,4,FALSE), "") | AL33: =COUNTIF(D33:AH33,"S") | AM33: =COUNTIF(D33:AH33,"I") | AN33: =COUNTIF(D33:AH33,"A") | AO33: =SUM(AL33:AN33)
A34: 28 | B34: =IFERROR(VLOOKUP(A34&$AJ$2,Data!$A$2:$AM$131,3,FALSE), "") | C34: =IFERROR(VLOOKUP(A34&$AJ$2,Data!$A$2:$AM$131,4,FALSE), "") | AL34: =COUNTIF(D34:AH34,"S") | AM34: =COUNTIF(D34:AH34,"I") | AN34: =COUNTIF(D34:AH34,"A") | AO34: =SUM(AL34:AN34)
A35: 29 | B35: =IFERROR(VLOOKUP(A35&$AJ$2,Data!$A$2:$AM$131,3,FALSE), "") | C35: =IFERROR(VLOOKUP(A35&$AJ$2,Data!$A$2:$AM$131,4,FALSE), "") | AL35: =COUNTIF(D35:AH35,"S") | AM35: =COUNTIF(D35:AH35,"I") | AN35: =COUNTIF(D35:AH35,"A") | AO35: =SUM(AL35:AN35)
A36: 30 | B36: =IFERROR(VLOOKUP(A36&$AJ$2,Data!$A$2:$AM$131,3,FALSE), "") | C36: =IFERROR(VLOOKUP(A36&$AJ$2,Data!$A$2:$AM$131,4,FALSE), "") | AL36: =COUNTIF(D36:AH36,"S") | AM36: =COUNTIF(D36:AH36,"I") | AN36: =COUNTIF(D36:AH36,"A") | AO36: =SUM(AL36:AN36)
A37: 31 | B37: =IFERROR(VLOOKUP(A37&$AJ$2,Data!$A$2:$AM$131,3,FALSE), "") | C37: =IFERROR(VLOOKUP(A37&$AJ$2,Data!$A$2:$AM$131,4,FALSE), "") | AL37: =COUNTIF(D37:AH37,"S") | AM37: =COUNTIF(D37:AH37,"I") | AN37: =COUNTIF(D37:AH37,"A") | AO37: =SUM(AL37:AN37)
A38: 32 | B38: =IFERROR(VLOOKUP(A38&$AJ$2,Data!$A$2:$AM$131,3,FALSE), "") | C38: =IFERROR(VLOOKUP(A38&$AJ$2,Data!$A$2:$AM$131,4,FALSE), "") | I38: S | J38: S | AL38: =COUNTIF(D38:AH38,"S") | AM38: =COUNTIF(D38:AH38,"I") | AN38: =COUNTIF(D38:AH38,"A") | AO38: =SUM(AL38:AN38)
A39: 33 | B39: =IFERROR(VLOOKUP(A39&$AJ$2,Data!$A$2:$AM$131,3,FALSE), "") | C39: =IFERROR(VLOOKUP(A39&$AJ$2,Data!$A$2:$AM$131,4,FALSE), "") | AL39: =COUNTIF(D39:AH39,"S") | AM39: =COUNTIF(D39:AH39,"I") | AN39: =COUNTIF(D39:AH39,"A") | AO39: =SUM(AL39:AN39)
A40: 34 | B40: =IFERROR(VLOOKUP(A40&$AJ$2,Data!$A$2:$AM$131,3,FALSE), "") | C40: =IFERROR(VLOOKUP(A40&$AJ$2,Data!$A$2:$AM$131,4,FALSE), "") | AL40: =COUNTIF(D40:AH40,"S") | AM40: =COUNTIF(D40:AH40,"I") | AN40: =COUNTIF(D40:AH40,"A") | AO40: =SUM(AL40:AN40)
...

Sheet TKB(2)
A1: 0 | U1: 0
A2: DAFTAR NAMA MURID T.P. 2025/2026 | AJ2: TKB2
A3: Kelas | C3: =" : " & IF(AJ2="","",AJ2)
A4: Walikelas | C4: =IFERROR(" : " &VLOOKUP($A$7&$AJ$2,#REF!,6,FALSE), "")
A5: Nomor | C5: Nama | D5: April
A6: Urt | B6: Induk | D6: 1 | E6: 2 | F6: 3 | G6: 4 | H6: 5 | I6: 6 | J6: 7 | K6: 8 | L6: 9 | M6: 10 | N6: 11 | O6: 12 | P6: 13 | Q6: 14 | R6: 15 | S6: 16 | T6: 17 | U6: 18 | V6: 19 | W6: 20 | X6: 21 | Y6: 22 | Z6: 23 | AA6: 24 | AB6: 25 | AC6: 26 | AD6: 27 | AE6: 28 | AF6: 29 | AG6: 30 | AH6: 31 | AL6: S | AM6: I | AN6: A | AO6: Total
A7: 1 | B7: =IFERROR(VLOOKUP(A7&$AJ$2,Data!$A$2:$AM$135,3,FALSE), "") | C7: =IFERROR(VLOOKUP(A7&$AJ$2,Data!$A$2:$AM$135,4,FALSE), "") | J7: I | S7: S | AK7: S | AL7: =COUNTIF(D7:AH7,"S") | AM7: =COUNTIF(D7:AH7,"I") | AN7: =COUNTIF(D7:AH7,"A") | AO7: =SUM(AL7:AN7)
A8: 2 | B8: =IFERROR(VLOOKUP(A8&$AJ$2,Data!$A$2:$AM$135,3,FALSE), "") | C8: =IFERROR(VLOOKUP(A8&$AJ$2,Data!$A$2:$AM$135,4,FALSE), "") | AK8: I | AL8: =COUNTIF(D8:AH8,"S") | AM8: =COUNTIF(D8:AH8,"I") | AN8: =COUNTIF(D8:AH8,"A") | AO8: =SUM(AL8:AN8)
A9: 3 | B9: =IFERROR(VLOOKUP(A9&$AJ$2,Data!$A$2:$AM$135,3,FALSE), "") | C9: =IFERROR(VLOOKUP(A9&$AJ$2,Data!$A$2:$AM$135,4,FALSE), "") | Q9: S | AK9: A | AL9: =COUNTIF(D9:AH9,"S") | AM9: =COUNTIF(D9:AH9,"I") | AN9: =COUNTIF(D9:AH9,"A") | AO9: =SUM(AL9:AN9)
A10: 4 | B10: =IFERROR(VLOOKUP(A10&$AJ$2,Data!$A$2:$AM$135,3,FALSE), "") | C10: =IFERROR(VLOOKUP(A10&$AJ$2,Data!$A$2:$AM$135,4,FALSE), "") | AK10: . | AL10: =COUNTIF(D10:AH10,"S") | AM10: =COUNTIF(D10:AH10,"I") | AN10: =COUNTIF(D10:AH10,"A") | AO10: =SUM(AL10:AN10)
A11: 5 | B11: =IFERROR(VLOOKUP(A11&$AJ$2,Data!$A$2:$AM$135,3,FALSE), "") | C11: =IFERROR(VLOOKUP(A11&$AJ$2,Data!$A$2:$AM$135,4,FALSE), "") | AL11: =COUNTIF(D11:AH11,"S") | AM11: =COUNTIF(D11:AH11,"I") | AN11: =COUNTIF(D11:AH11,"A") | AO11: =SUM(AL11:AN11)
A12: 6 | B12: =IFERROR(VLOOKUP(A12&$AJ$2,Data!$A$2:$AM$135,3,FALSE), "") | C12: =IFERROR(VLOOKUP(A12&$AJ$2,Data!$A$2:$AM$135,4,FALSE), "") | I12: S | K12: S | AL12: =COUNTIF(D12:AH12,"S") | AM12: =COUNTIF(D12:AH12,"I") | AN12: =COUNTIF(D12:AH12,"A") | AO12: =SUM(AL12:AN12)
A13: 7 | B13: =IFERROR(VLOOKUP(A13&$AJ$2,Data!$A$2:$AM$135,3,FALSE), "") | C13: =IFERROR(VLOOKUP(A13&$AJ$2,Data!$A$2:$AM$135,4,FALSE), "") | AL13: =COUNTIF(D13:AH13,"S") | AM13: =COUNTIF(D13:AH13,"I") | AN13: =COUNTIF(D13:AH13,"A") | AO13: =SUM(AL13:AN13)
A14: 8 | B14: =IFERROR(VLOOKUP(A14&$AJ$2,Data!$A$2:$AM$135,3,FALSE), "") | C14: =IFERROR(VLOOKUP(A14&$AJ$2,Data!$A$2:$AM$135,4,FALSE), "") | AL14: =COUNTIF(D14:AH14,"S") | AM14: =COUNTIF(D14:AH14,"I") | AN14: =COUNTIF(D14:AH14,"A") | AO14: =SUM(AL14:AN14)
A15: 9 | B15: =IFERROR(VLOOKUP(A15&$AJ$2,Data!$A$2:$AM$135,3,FALSE), "") | C15: =IFERROR(VLOOKUP(A15&$AJ$2,Data!$A$2:$AM$135,4,FALSE), "") | AL15: =COUNTIF(D15:AH15,"S") | AM15: =COUNTIF(D15:AH15,"I") | AN15: =COUNTIF(D15:AH15,"A") | AO15: =SUM(AL15:AN15)
A16: 10 | B16: =IFERROR(VLOOKUP(A16&$AJ$2,Data!$A$2:$AM$135,3,FALSE), "") | C16: =IFERROR(VLOOKUP(A16&$AJ$2,Data!$A$2:$AM$135,4,FALSE), "") | AL16: =COUNTIF(D16:AH16,"S") | AM16: =COUNTIF(D16:AH16,"I") | AN16: =COUNTIF(D16:AH16,"A") | AO16: =SUM(AL16:AN16)
A17: 11 | B17: =IFERROR(VLOOKUP(A17&$AJ$2,Data!$A$2:$AM$135,3,FALSE), "") | C17: =IFERROR(VLOOKUP(A17&$AJ$2,Data!$A$2:$AM$135,4,FALSE), "") | AL17: =COUNTIF(D17:AH17,"S") | AM17: =COUNTIF(D17:AH17,"I") | AN17: =COUNTIF(D17:AH17,"A") | AO17: =SUM(AL17:AN17)
A18: 12 | B18: =IFERROR(VLOOKUP(A18&$AJ$2,Data!$A$2:$AM$135,3,FALSE), "") | C18: =IFERROR(VLOOKUP(A18&$AJ$2,Data!$A$2:$AM$135,4,FALSE), "") | AL18: =COUNTIF(D18:AH18,"S") | AM18: =COUNTIF(D18:AH18,"I") | AN18: =COUNTIF(D18:AH18,"A") | AO18: =SUM(AL18:AN18)
A19: 13 | B19: =IFERROR(VLOOKUP(A19&$AJ$2,Data!$A$2:$AM$135,3,FALSE), "") | C19: =IFERROR(VLOOKUP(A19&$AJ$2,Data!$A$2:$AM$135,4,FALSE), "") | AL19: =COUNTIF(D19:AH19,"S") | AM19: =COUNTIF(D19:AH19,"I") | AN19: =COUNTIF(D19:AH19,"A") | AO19: =SUM(AL19:AN19)
A20: 14 | B20: =IFERROR(VLOOKUP(A20&$AJ$2,Data!$A$2:$AM$135,3,FALSE), "") | C20: =IFERROR(VLOOKUP(A20&$AJ$2,Data!$A$2:$AM$135,4,FALSE), "") | D20: S | E20: S | AL20: =COUNTIF(D20:AH20,"S") | AM20: =COUNTIF(D20:AH20,"I") | AN20: =COUNTIF(D20:AH20,"A") | AO20: =SUM(AL20:AN20)
A21: 15 | B21: =IFERROR(VLOOKUP(A21&$AJ$2,Data!$A$2:$AM$135,3,FALSE), "") | C21: =IFERROR(VLOOKUP(A21&$AJ$2,Data!$A$2:$AM$135,4,FALSE), "") | AL21: =COUNTIF(D21:AH21,"S") | AM21: =COUNTIF(D21:AH21,"I") | AN21: =COUNTIF(D21:AH21,"A") | AO21: =SUM(AL21:AN21)
A22: 16 | B22: =IFERROR(VLOOKUP(A22&$AJ$2,Data!$A$2:$AM$135,3,FALSE), "") | C22: =IFERROR(VLOOKUP(A22&$AJ$2,Data!$A$2:$AM$135,4,FALSE), "") | AL22: =COUNTIF(D22:AH22,"S") | AM22: =COUNTIF(D22:AH22,"I") | AN22: =COUNTIF(D22:AH22,"A") | AO22: =SUM(AL22:AN22)
A23: 17 | B23: =IFERROR(VLOOKUP(A23&$AJ$2,Data!$A$2:$AM$135,3,FALSE), "") | C23: =IFERROR(VLOOKUP(A23&$AJ$2,Data!$A$2:$AM$135,4,FALSE), "") | L23: S | P23: S | Q23: S | R23: S | AL23: =COUNTIF(D23:AH23,"S") | AM23: =COUNTIF(D23:AH23,"I") | AN23: =COUNTIF(D23:AH23,"A") | AO23: =SUM(AL23:AN23)
A24: 18 | B24: =IFERROR(VLOOKUP(A24&$AJ$2,Data!$A$2:$AM$135,3,FALSE), "") | C24: =IFERROR(VLOOKUP(A24&$AJ$2,Data!$A$2:$AM$135,4,FALSE), "") | AL24: =COUNTIF(D24:AH24,"S") | AM24: =COUNTIF(D24:AH24,"I") | AN24: =COUNTIF(D24:AH24,"A") | AO24: =SUM(AL24:AN24)
A25: 19 | B25: =IFERROR(VLOOKUP(A25&$AJ$2,Data!$A$2:$AM$135,3,FALSE), "") | C25: =IFERROR(VLOOKUP(A25&$AJ$2,Data!$A$2:$AM$135,4,FALSE), "") | AL25: =COUNTIF(D25:AH25,"S") | AM25: =COUNTIF(D25:AH25,"I") | AN25: =COUNTIF(D25:AH25,"A") | AO25: =SUM(AL25:AN25)
A26: 20 | B26: =IFERROR(VLOOKUP(A26&$AJ$2,Data!$A$2:$AM$135,3,FALSE), "") | C26: =IFERROR(VLOOKUP(A26&$AJ$2,Data!$A$2:$AM$135,4,FALSE), "") | AL26: =COUNTIF(D26:AH26,"S") | AM26: =COUNTIF(D26:AH26,"I") | AN26: =COUNTIF(D26:AH26,"A") | AO26: =SUM(AL26:AN26)
A27: 21 | B27: =IFERROR(VLOOKUP(A27&$AJ$2,Data!$A$2:$AM$135,3,FALSE), "") | C27: =IFERROR(VLOOKUP(A27&$AJ$2,Data!$A$2:$AM$135,4,FALSE), "") | L27: S | AL27: =COUNTIF(D27:AH27,"S") | AM27: =COUNTIF(D27:AH27,"I") | AN27: =COUNTIF(D27:AH27,"A") | AO27: =SUM(AL27:AN27)
A28: 22 | B28: =IFERROR(VLOOKUP(A28&$AJ$2,Data!$A$2:$AM$135,3,FALSE), "") | C28: =IFERROR(VLOOKUP(A28&$AJ$2,Data!$A$2:$AM$135,4,FALSE), "") | P28: S | AL28: =COUNTIF(D28:AH28,"S") | AM28: =COUNTIF(D28:AH28,"I") | AN28: =COUNTIF(D28:AH28,"A") | AO28: =SUM(AL28:AN28)
A29: 23 | B29: =IFERROR(VLOOKUP(A29&$AJ$2,Data!$A$2:$AM$135,3,FALSE), "") | C29: =IFERROR(VLOOKUP(A29&$AJ$2,Data!$A$2:$AM$135,4,FALSE), "") | AL29: =COUNTIF(D29:AH29,"S") | AM29: =COUNTIF(D29:AH29,"I") | AN29: =COUNTIF(D29:AH29,"A") | AO29: =SUM(AL29:AN29)
A30: 24 | B30: =IFERROR(VLOOKUP(A30&$AJ$2,Data!$A$2:$AM$135,3,FALSE), "") | C30: =IFERROR(VLOOKUP(A30&$AJ$2,Data!$A$2:$AM$135,4,FALSE), "") | AL30: =COUNTIF(D30:AH30,"S") | AM30: =COUNTIF(D30:AH30,"I") | AN30: =COUNTIF(D30:AH30,"A") | AO30: =SUM(AL30:AN30)
A31: 25 | B31: =IFERROR(VLOOKUP(A31&$AJ$2,Data!$A$2:$AM$135,3,FALSE), "") | C31: =IFERROR(VLOOKUP(A31&$AJ$2,Data!$A$2:$AM$135,4,FALSE), "") | S31: S | AL31: =COUNTIF(D31:AH31,"S") | AM31: =COUNTIF(D31:AH31,"I") | AN31: =COUNTIF(D31:AH31,"A") | AO31: =SUM(AL31:AN31)
A32: 26 | B32: =IFERROR(VLOOKUP(A32&$AJ$2,Data!$A$2:$AM$135,3,FALSE), "") | C32: =IFERROR(VLOOKUP(A32&$AJ$2,Data!$A$2:$AM$135,4,FALSE), "") | D32: S | AL32: =COUNTIF(D32:AH32,"S") | AM32: =COUNTIF(D32:AH32,"I") | AN32: =COUNTIF(D32:AH32,"A") | AO32: =SUM(AL32:AN32)
A33: 27 | B33: =IFERROR(VLOOKUP(A33&$AJ$2,Data!$A$2:$AM$135,3,FALSE), "") | C33: =IFERROR(VLOOKUP(A33&$AJ$2,Data!$A$2:$AM$135,4,FALSE), "") | AL33: =COUNTIF(D33:AH33,"S") | AM33: =COUNTIF(D33:AH33,"I") | AN33: =COUNTIF(D33:AH33,"A") | AO33: =SUM(AL33:AN33)
A34: 28 | B34: =IFERROR(VLOOKUP(A34&$AJ$2,Data!$A$2:$AM$135,3,FALSE), "") | C34: =IFERROR(VLOOKUP(A34&$AJ$2,Data!$A$2:$AM$135,4,FALSE), "") | R34: S | S34: S | AL34: =COUNTIF(D34:AH34,"S") | AM34: =COUNTIF(D34:AH34,"I") | AN34: =COUNTIF(D34:AH34,"A") | AO34: =SUM(AL34:AN34)
A35: 29 | B35: =IFERROR(VLOOKUP(A35&$AJ$2,Data!$A$2:$AM$135,3,FALSE), "") | C35: =IFERROR(VLOOKUP(A35&$AJ$2,Data!$A$2:$AM$135,4,FALSE), "") | AL35: =COUNTIF(D35:AH35,"S") | AM35: =COUNTIF(D35:AH35,"I") | AN35: =COUNTIF(D35:AH35,"A") | AO35: =SUM(AL35:AN35)
A36: 30 | B36: =IFERROR(VLOOKUP(A36&$AJ$2,Data!$A$2:$AM$135,3,FALSE), "") | C36: =IFERROR(VLOOKUP(A36&$AJ$2,Data!$A$2:$AM$135,4,FALSE), "") | AL36: =COUNTIF(D36:AH36,"S") | AM36: =COUNTIF(D36:AH36,"I") | AN36: =COUNTIF(D36:AH36,"A") | AO36: =SUM(AL36:AN36)
A37: 31 | B37: =IFERROR(VLOOKUP(A37&$AJ$2,Data!$A$2:$AM$135,3,FALSE), "") | C37: =IFERROR(VLOOKUP(A37&$AJ$2,Data!$A$2:$AM$135,4,FALSE), "") | P37: S | Q37: S | AL37: =COUNTIF(D37:AH37,"S") | AM37: =COUNTIF(D37:AH37,"I") | AN37: =COUNTIF(D37:AH37,"A") | AO37: =SUM(AL37:AN37)
A38: 32 | B38: =IFERROR(VLOOKUP(A38&$AJ$2,Data!$A$2:$AM$135,3,FALSE), "") | C38: =IFERROR(VLOOKUP(A38&$AJ$2,Data!$A$2:$AM$135,4,FALSE), "") | P38: S | Q38: S | AL38: =COUNTIF(D38:AH38,"S") | AM38: =COUNTIF(D38:AH38,"I") | AN38: =COUNTIF(D38:AH38,"A") | AO38: =SUM(AL38:AN38)
A39: 33 | B39: =IFERROR(VLOOKUP(A39&$AJ$2,Data!$A$2:$AM$135,3,FALSE), "") | C39: =IFERROR(VLOOKUP(A39&$AJ$2,Data!$A$2:$AM$135,4,FALSE), "") | AL39: =COUNTIF(D39:AH39,"S") | AM39: =COUNTIF(D39:AH39,"I") | AN39: =COUNTIF(D39:AH39,"A") | AO39: =SUM(AL39:AN39)
A40: 34 | B40: =IFERROR(VLOOKUP(A40&$AJ$2,Data!$A$2:$AM$135,3,FALSE), "") | C40: =IFERROR(VLOOKUP(A40&$AJ$2,Data!$A$2:$AM$135,4,FALSE), "") | D40: I | E40: A | R40: S | AL40: =COUNTIF(D40:AH40,"S") | AM40: =COUNTIF(D40:AH40,"I") | AN40: =COUNTIF(D40:AH40,"A") | AO40: =SUM(AL40:AN40)
...

Sheet Data
H2: Januari | I2: S | J2: PG
H3: Februari | I3: I | J3: TKA
A4: =B4&E4 | B4: 1 | C4: 0221 | D4: Edbert Reynaldo Lim | E4: PG | F4: Lina | H4: Maret | I4: A | J4: TKB1
A5: =B5&E5 | B5: 2 | C5: 0228 | D5: Axelle Tiandra Ong | E5: PG | F5: Lina | H5: April | I5: ? | J5: TKB2
A6: =B6&E6 | B6: 3 | C6: 0229 | D6: Carencya Chailinskie | E6: PG | F6: Lina | H6: Mei | I6: .
A7: =B7&E7 | B7: 4 | C7: 0230 | D7: Elvano Leonardi | E7: PG | F7: Lina | H7: Juni
A8: =B8&E8 | B8: 5 | C8: 0231 | D8: Evano Ryu Tanzil | E8: PG | F8: Lina | H8: Juli
A9: =B9&E9 | B9: 6 | C9: 0232 | D9: Gareth Grealish Dharmawan | E9: PG | F9: Lina | H9: Agustus
A10: =B10&E10 | B10: 7 | C10: 0233 | D10: Joverick Walton | E10: PG | F10: Lina | H10: September
A11: =B11&E11 | B11: 8 | C11: 0234 | D11: Kaylyn Gavril Winlie | E11: PG | F11: Lina | H11: Oktober
A12: =B12&E12 | B12: 9 | C12: 0235 | D12: Rachel Crystaline Benyamin | E12: PG | F12: Lina | H12: November
A13: =B13&E13 | B13: 10 | C13: 0236 | D13: Rachel Veisya Chan | E13: PG | F13: Lina | H13: Desember
A14: =B14&E14 | B14: 11 | C14: 0237 | D14: Rachellyn Gracia Chindra | E14: PG | F14: Lina
A15: =B15&E15 | B15: 12 | D15: Roderick Yang | E15: PG | F15: Lina
A16: =B16&E16
A17: =B17&E17
A18: =B18&E18
A19: =B19&E19 | B19: 1 | C19: 1505 | D19: Aldrich Bona Munson Nababan | E19: TKA | F19: Elizabet, S.Pd.
A20: =B20&E20 | B20: 2 | C20: 1506 | D20: Azka Andreas | E20: TKA | F20: Elizabet, S.Pd.
A21: =B21&E21 | B21: 3 | C21: 1507 | D21: Celine Grace Zhang | E21: TKA | F21: Elizabet, S.Pd.
A22: =B22&E22 | B22: 4 | C22: 1508 | D22: Clarence Queenicca Zhang | E22: TKA | F22: Elizabet, S.Pd.
A23: =B23&E23 | B23: 5 | C23: 1509 | D23: Clarissa Jovanka Sugiharto | E23: TKA | F23: Elizabet, S.Pd.
A24: =B24&E24 | B24: 6 | C24: 1510 | D24: Clarissa Lim | E24: TKA | F24: Elizabet, S.Pd.
A25: =B25&E25 | B25: 7 | C25: 1511 | D25: Clarita Olivia Sinaga | E25: TKA | F25: Elizabet, S.Pd.
A26: =B26&E26 | B26: 8 | C26: 1512 | D26: Coryn Aurora Zhan | E26: TKA | F26: Elizabet, S.Pd.
A27: =B27&E27 | B27: 9 | C27: 1513 | D27: Darren Elvano | E27: TKA | F27: Elizabet, S.Pd.
A28: =B28&E28 | B28: 10 | C28: 1514 | D28: Darren Tristan | E28: TKA | F28: Elizabet, S.Pd.
A29: =B29&E29 | B29: 11 | C29: 1515 | D29: Davian Kenrick Lu | E29: TKA | F29: Elizabet, S.Pd.
A30: =B30&E30 | B30: 12 | C30: 1516 | D30: Devan Ivander Siahaan | E30: TKA | F30: Elizabet, S.Pd.
... A48: =B48&E48 | B48: 30 | C48: 1534 | D48: Willian Geoffrey Utama | E48: TKA | F48: Elizabet, S.Pd.
A49: =B49&E49 | B49: 31
A50: =B50&E50 | B50: 32
A51: =B51&E51 | B51: 33
A52: =B52&E52
A53: =B53&E53
A54: =B54&E54
A55: =B55&E55
A56: =B56&E56
A57: =B57&E57
A58: =B58&E58 | B58: 1 | C58: 1439 | D58: Kyla Nathania Chang | E58: TKB1 | F58: Juliana Krisnawati Saragih, S.Si.
...
